Workbook

Sheet Portada
B2: Calculadora de Dimensionamiento – Sitio Web 3 Capas en Azure
B4: Proyecto: | C4: Sitio Web 3 capas (WAF + App React/API + Base de Datos) – Estimación de capacidad
B5: Alcance: | C5: Estimación de Almacenamiento (Storage), CPU, RAM y Red (Network) en Azure
B6: Fecha: | C6: Septiembre 2026
B8: Cómo usar este archivo
B9: 1. Vaya a la pestaña 'Supuestos' y edite ÚNICAMENTE las celdas resaltadas en AMARILLO (texto azul). Son los datos conocidos de su operación.
B10: 2. Las demás pestañas (Almacenamiento, Computo, Red, Resumen) se recalculan automáticamente con fórmulas — no requieren edición.
B11: 3. La pestaña 'Resumen' muestra los resultados clave por año (Año 0 = hoy, Año 1-3 = proyección) y una sugerencia de SKU de Azure de referencia.
B12: 4. Todos los supuestos usados están documentados junto a cada celda (columna de notas) para que pueda ajustarlos según valide con el negocio.
B14: Leyenda de colores
B15: Texto azul + relleno amarillo | C15: Dato de entrada editable (supuesto)
B16: Texto negro | C16: Fórmula calculada — no editar
B17: Texto verde | C17: Enlace/valor traído de otra pestaña
B18: Relleno verde claro | C18: Resultado final / recomendación
B20: Importante
B21: Esta calculadora entrega un DIMENSIONAMIENTO ESTIMADO (orden de magnitud) basado en supuestos de uso declarados y en reglas generales de la industria (rules of thumb). No reemplaza un ejercicio de pruebas de carga (load testing), el uso de Azure Monitor/Application Insights con datos reales, ni el Azure Pricing Calculator / Well-Architected Framework para el dimensionamiento final de producción. En particular, el dimensionamiento de Azure WAF/Application Gateway (Capacity Units) depende de reglas OWASP habilitadas y del motor de autoescalado de Azure, por lo que aquí solo se entrega el ancho de banda y las conexiones estimadas como INSUMO para validar la capacidad en la documentación oficial de Azure.

Sheet Supuestos
A1: Supuestos de Entrada (editar solo celdas amarillas)
A3: 1. Usuarios, clientes y crecimiento
A4: Usuarios concurrentes pico (hoy) | B4: 100 | C4: usuarios | D4: Dato provisto por el negocio: 100 usuarios concurrentes durante el día.
A5: Usuarios totales registrados (todas las sucursales) | B5: 300 | C5: usuarios | D5: Base de usuarios que rota durante el día para llegar a 100 concurrentes en pico. Ajustar según nómina real de sucursales.
A6: Clientes gestionados en el sistema | B6: 500 | C6: clientes | D6: Volumen de clientes de uso promedio indicado por el negocio.
A7: Tasa de crecimiento anual (usuarios, datos y transacciones) | B7: 0.2 | C7: % | D7: Supuesto de crecimiento del negocio/sucursales. Ajustar según plan de expansión real.
A8: Años de proyección | B8: 3 | C8: años | D8: Horizonte de la proyección solicitado.
A9: Días hábiles por mes | B9: 22 | C9: días | D9: Estándar de días laborables.
A10: Horas laborales por día (ventana de uso del sistema) | B10: 10 | C10: horas | D10: Ventana en la que se concentra el uso concurrente (p.ej. 8:00-18:00).
A12: 2. Documentos e imágenes (por usuario)
A13: Documentos subidos por usuario por día | B13: 5 | C13: docs/usuario/día | D13: Promedio estimado de documentos que sube cada usuario activo al día.
A14: Tamaño promedio de documento | B14: 6.5 | C14: MB | D14: Promedio del rango informado por el negocio (3 a 10 MB).
A15: Imágenes subidas por usuario por día | B15: 3 | C15: imgs/usuario/día | D15: Promedio estimado de imágenes que sube cada usuario activo al día.
A16: Tamaño promedio de imagen | B16: 3 | C16: MB | D16: Promedio del rango informado por el negocio (1 a 5 MB).
A17: Años de retención de documentos e imágenes | B17: 5 | C17: años | D17: Definido por el negocio. Como es mayor al horizonte de proyección (3 años), nada se elimina dentro de la proyección.
A18: Overhead por metadatos / miniaturas (thumbnails) | B18: 0.1 | C18: % | D18: % adicional sobre el peso de archivos originales por copias/miniaturas generadas.
A20: 3. Base de datos (Azure SQL Database)
A21: Tamaño promedio registro de cliente | B21: 2 | C21: KB | D21: Fila de cliente con sus atributos (razón social, contacto, etc.).
A22: Tamaño promedio registro de usuario | B22: 1 | C22: KB | D22: Fila de usuario del sistema (perfil, permisos).
A23: Transacciones/solicitudes por usuario por día | B23: 20 | C23: trans/usuario/día | D23: Operaciones de negocio (altas, consultas guardadas, actualizaciones) por usuario activo.
A24: Tamaño promedio por transacción (incl. bitácora/auditoría) | B24: 2.5 | C24: KB | D24: Peso de fila transaccional + registro de auditoría asociado.
A25: Reportes generados por día (todos los usuarios) | B25: 30 | C25: reportes/día | D25: Reportes con metadatos guardados en base de datos (el archivo final se asume en Blob Storage, no aquí).
A26: Tamaño promedio de metadata de reporte en BD | B26: 1 | C26: KB | D26: Solo el registro/metadata en BD, no el binario del reporte.
A27: Overhead de índices y estructuras internas de BD | B27: 0.3 | C27: % | D27: % adicional típico por índices, log de transacciones y estructuras internas de SQL Server.
A29: 4. Cómputo — Capa de aplicación (React + API / App Service)
A30: Usuarios concurrentes atendidos por vCPU | B30: 50 | C30: usuarios/vCPU | D30: Regla general para carga típica CRUD + API REST. Validar con pruebas de carga reales; workloads más pesados (ej. procesamiento de imágenes) requieren menos usuarios por vCPU.
A31: RAM base de runtime por instancia (SO + framework) | B31: 1.5 | C31: GB | D31: Memoria base de Node.js/.NET + sistema operativo del App Service, antes de atender usuarios.
A32: RAM adicional por usuario concurrente (sesión/caché) | B32: 0.03 | C32: GB/usuario | D32: Memoria estimada por sesión activa/caché de aplicación.
A33: Margen de seguridad (headroom) para picos - App | B33: 0.3 | C33: % | D33: Colchón adicional recomendado para absorber picos no planificados.
A34: Instancias mínimas por alta disponibilidad | B34: 2 | C34: instancias | D34: Mínimo recomendado para tener redundancia (zona/instancia) en producción.
A36: 5. Cómputo — Capa de base de datos (Azure SQL vCore)
A37: Transacciones (lectura+escritura) que soporta 1 vCore | B37: 70 | C37: trans/seg/vCore | D37: Regla general para OLTP ligero-moderado en Azure SQL General Purpose. Ajustar según complejidad real de consultas.
A38: RAM aproximada por vCore (tier General Purpose, Gen5) | B38: 5.1 | C38: GB/vCore | D38: Referencia pública de Microsoft para Azure SQL Database General Purpose (aprox. 5.1 GB de memoria por vCore).
A39: Margen de seguridad (headroom) para picos - BD | B39: 0.3 | C39: % | D39: Colchón adicional recomendado para absorber picos no planificados.
A40: Factor de concentración de carga en hora pico | B40: 3 | C40: x | D40: Las transacciones no se distribuyen uniformemente en el día; este factor castiga el promedio para estimar el pico horario/por segundo.
A42: 6. Red y WAF (Application Gateway / Front Door)
A43: % de usuarios concurrentes subiendo archivos a la vez (pico) | B43: 0.15 | C43: % | D43: Fracción de los usuarios concurrentes que coinciden subiendo un documento/imagen al mismo tiempo.
A44: Tiempo objetivo de carga de un archivo | B44: 10 | C44: segundos | D44: Tiempo máximo aceptable para que un usuario termine de subir su archivo.
A45: Tamaño promedio de solicitud/respuesta API (JSON) | B45: 15 | C45: KB | D45: Peso típico de una llamada API (request+response) de listados, formularios, etc.
A46: Solicitudes API por usuario por minuto | B46: 6 | C46: solic./usuario/min | D46: Interacciones promedio (clics que disparan llamadas al API) por usuario activo.
...

Sheet Almacenamiento
A1: Almacenamiento (Storage) — Blob (documentos/imágenes) + Azure SQL (datos)
A3: Concepto | B3: Año 0 (hoy) | C3: Año 1 | D3: Año 2 | E3: Año 3 | F3: Nota / fórmula
A4: A. Almacenamiento de archivos (Azure Blob Storage) — documentos e imágenes
A5: Usuarios totales (proyectados) | B5: =Supuestos!$B$5*(1+Supuestos!$B$7)^0 -> 300 | C5: =Supuestos!$B$5*(1+Supuestos!$B$7)^1 -> 360 | D5: =Supuestos!$B$5*(1+Supuestos!$B$7)^2 -> 432 | E5: =Supuestos!$B$5*(1+Supuestos!$B$7)^3 -> 518.4 | F5: Usuarios totales x (1+crecimiento)^año
A6: MB generados por día (docs + imágenes, con overhead) | B6: =(B5*Supuestos!$B$13*Supuestos!$B$14+B5*Supuestos!$B$15*Supuestos!$B$16)*(1+Supuestos!$B$18) -> 13695 | C6: =(C5*Supuestos!$B$13*Supuestos!$B$14+C5*Supuestos!$B$15*Supuestos!$B$16)*(1+Supuestos!$B$18) -> 16434 | D6: =(D5*Supuestos!$B$13*Supuestos!$B$14+D5*Supuestos!$B$15*Supuestos!$B$16)*(1+Supuestos!$B$18) -> 19720.8 | E6: =(E5*Supuestos!$B$13*Supuestos!$B$14+E5*Supuestos!$B$15*Supuestos!$B$16)*(1+Supuestos!$B$18) -> 23664.96 | F6: (usuarios x docs/día x MB/doc + usuarios x imgs/día x MB/img) x (1+overhead metadatos)
A7: GB generados durante ese año | B7: =B6*Supuestos!$B$9*12/1024 -> 3530.7422 | C7: =C6*Supuestos!$B$9*12/1024 -> 4236.8906 | D7: =D6*Supuestos!$B$9*12/1024 -> 5084.2688 | E7: =E6*Supuestos!$B$9*12/1024 -> 6101.1225 | F7: MB/día x días hábiles/mes x 12 meses / 1024 (MB->GB)
A8: GB acumulados en Blob Storage (fin de año) | B8: =B7 -> 3530.7422 | C8: =B8+C7 -> 7767.6328 | D8: =C8+D7 -> 12851.902 | E8: =D8+E7 -> 18953.024 | F8: Acumulado = año anterior + generado este año. No se resta nada porque la retención (5 años) es mayor al horizonte de 3 años proyectado.
A10: B. Almacenamiento de base de datos (Azure SQL Database)
A11: Clientes gestionados (proyectados) | B11: =Supuestos!$B$6*(1+Supuestos!$B$7)^0 -> 500 | C11: =Supuestos!$B$6*(1+Supuestos!$B$7)^1 -> 600 | D11: =Supuestos!$B$6*(1+Supuestos!$B$7)^2 -> 720 | E11: =Supuestos!$B$6*(1+Supuestos!$B$7)^3 -> 864
A12: Datos maestros: clientes + usuarios (KB) | B12: =B11*Supuestos!$B$21+B5*Supuestos!$B$22 -> 1300 | C12: =C11*Supuestos!$B$21+C5*Supuestos!$B$22 -> 1560 | D12: =D11*Supuestos!$B$21+D5*Supuestos!$B$22 -> 1872 | E12: =E11*Supuestos!$B$21+E5*Supuestos!$B$22 -> 2246.4 | F12: clientes x KB/cliente + usuarios x KB/usuario
A13: Transacciones + reportes generados por día (KB) | B13: =B5*Supuestos!$B$23*Supuestos!$B$24+Supuestos!$B$25*Supuestos!$B$26 -> 15030 | C13: =C5*Supuestos!$B$23*Supuestos!$B$24+Supuestos!$B$25*Supuestos!$B$26 -> 18030 | D13: =D5*Supuestos!$B$23*Supuestos!$B$24+Supuestos!$B$25*Supuestos!$B$26 -> 21630 | E13: =E5*Supuestos!$B$23*Supuestos!$B$24+Supuestos!$B$25*Supuestos!$B$26 -> 25950 | F13: usuarios x trans/día x KB/trans + reportes/día x KB/reporte
A14: GB transaccionales generados durante ese año | B14: =B13*Supuestos!$B$9*12/1024/1024 -> 3.7841034 | C14: =C13*Supuestos!$B$9*12/1024/1024 -> 4.5394135 | D14: =D13*Supuestos!$B$9*12/1024/1024 -> 5.4457855 | E14: =E13*Supuestos!$B$9*12/1024/1024 -> 6.533432 | F14: KB/día x días hábiles/mes x 12 / 1024 / 1024 (KB->GB)
A15: GB transaccionales acumulados (fin de año) | B15: =B14 -> 3.7841034 | C15: =B15+C14 -> 8.3235168 | D15: =C15+D14 -> 13.769302 | E15: =D15+E14 -> 20.302734
A16: GB totales en Azure SQL (maestros + transaccional + overhead índices) | B16: =(B12/1024/1024+B15)*(1+Supuestos!$B$27) -> 4.9209461 | C16: =(C12/1024/1024+C15)*(1+Supuestos!$B$27) -> 10.822506 | D16: =(D12/1024/1024+D15)*(1+Supuestos!$B$27) -> 17.902414 | E16: =(E12/1024/1024+E15)*(1+Supuestos!$B$27) -> 26.39634 | F16: (maestros en GB + transaccional acumulado) x (1+overhead de índices)
A18: C. Total de almacenamiento requerido
A19: TOTAL Almacenamiento (Blob + Azure SQL) — GB | B19: =B8+B16 -> 3535.6631 | C19: =C8+C16 -> 7778.4553 | D19: =D8+D16 -> 12869.804 | E19: =E8+E16 -> 18979.42 | F19: Blob acumulado + Azure SQL total
A20: TOTAL Almacenamiento — TB | B20: =B19/1024 -> 3.452796 | C20: =C19/1024 -> 7.5961478 | D20: =D19/1024 -> 12.568168 | E20: =E19/1024 -> 18.53459

Sheet Computo
A1: Cómputo — CPU y RAM (Capa Aplicación y Capa Base de Datos)
A3: Concepto | B3: Año 0 (hoy) | C3: Año 1 | D3: Año 2 | E3: Año 3 | F3: Nota / fórmula
A4: A. Capa de Aplicación (React + API, ej. Azure App Service)
A5: Usuarios concurrentes pico (proyectados) | B5: =Supuestos!$B$4*(1+Supuestos!$B$7)^0 -> 100 | C5: =Supuestos!$B$4*(1+Supuestos!$B$7)^1 -> 120 | D5: =Supuestos!$B$4*(1+Supuestos!$B$7)^2 -> 144 | E5: =Supuestos!$B$4*(1+Supuestos!$B$7)^3 -> 172.8
A6: vCPU necesarios (App Tier) | B6: =ROUNDUP((B5/Supuestos!$B$30)*(1+Supuestos!$B$33),0) -> 3 | C6: =ROUNDUP((C5/Supuestos!$B$30)*(1+Supuestos!$B$33),0) -> 4 | D6: =ROUNDUP((D5/Supuestos!$B$30)*(1+Supuestos!$B$33),0) -> 4 | E6: =ROUNDUP((E5/Supuestos!$B$30)*(1+Supuestos!$B$33),0) -> 5 | F6: ROUNDUP( usuarios concurrentes / usuarios-por-vCPU x (1+margen) )
A7: vCPU totales considerando alta disponibilidad (mín. instancias) | B7: =MAX(B6,Supuestos!$B$34) -> 3 | C7: =MAX(C6,Supuestos!$B$34) -> 4 | D7: =MAX(D6,Supuestos!$B$34) -> 4 | E7: =MAX(E6,Supuestos!$B$34) -> 5 | F7: El mayor entre vCPU necesarios y el mínimo de instancias por HA (1 vCPU asumido por instancia mínima)
A8: RAM necesaria — App Tier (GB) | B8: =(Supuestos!$B$31*Supuestos!$B$34+Supuestos!$B$32*B5)*(1+Supuestos!$B$33) -> 7.8 | C8: =(Supuestos!$B$31*Supuestos!$B$34+Supuestos!$B$32*C5)*(1+Supuestos!$B$33) -> 8.58 | D8: =(Supuestos!$B$31*Supuestos!$B$34+Supuestos!$B$32*D5)*(1+Supuestos!$B$33) -> 9.516 | E8: =(Supuestos!$B$31*Supuestos!$B$34+Supuestos!$B$32*E5)*(1+Supuestos!$B$33) -> 10.6392 | F8: (RAM base x instancias mínimas + RAM/usuario x usuarios concurrentes) x (1+margen)
A10: B. Capa de Base de Datos (Azure SQL Database)
A11: Transacciones totales por día (proyectadas) | B11: =Almacenamiento!B5*Supuestos!$B$23 -> 6000 | C11: =Almacenamiento!C5*Supuestos!$B$23 -> 7200 | D11: =Almacenamiento!D5*Supuestos!$B$23 -> 8640 | E11: =Almacenamiento!E5*Supuestos!$B$23 -> 10368 | F11: Usuarios totales proyectados (hoja Almacenamiento) x transacciones/usuario/día
A12: Transacciones por segundo en hora pico | B12: =(B11/(Supuestos!$B$10*3600))*Supuestos!$B$40 -> 0.5 | C12: =(C11/(Supuestos!$B$10*3600))*Supuestos!$B$40 -> 0.6 | D12: =(D11/(Supuestos!$B$10*3600))*Supuestos!$B$40 -> 0.72 | E12: =(E11/(Supuestos!$B$10*3600))*Supuestos!$B$40 -> 0.864 | F12: (transacciones/día / (horas laborales x 3600 seg)) x factor de concentración en pico
A13: vCores necesarios (Azure SQL Database) | B13: =ROUNDUP((B12/Supuestos!$B$37)*(1+Supuestos!$B$39),0) -> 1 | C13: =ROUNDUP((C12/Supuestos!$B$37)*(1+Supuestos!$B$39),0) -> 1 | D13: =ROUNDUP((D12/Supuestos!$B$37)*(1+Supuestos!$B$39),0) -> 1 | E13: =ROUNDUP((E12/Supuestos!$B$37)*(1+Supuestos!$B$39),0) -> 1 | F13: ROUNDUP( trans/seg pico / trans-por-vCore x (1+margen) )
A14: vCores totales (mínimo 2 vCores recomendado por Azure) | B14: =MAX(B13,2) -> 2 | C14: =MAX(C13,2) -> 2 | D14: =MAX(D13,2) -> 2 | E14: =MAX(E13,2) -> 2
A15: RAM aproximada — Base de Datos (GB) | B15: =B14*Supuestos!$B$38 -> 10.2 | C15: =C14*Supuestos!$B$38 -> 10.2 | D15: =D14*Supuestos!$B$38 -> 10.2 | E15: =E14*Supuestos!$B$38 -> 10.2 | F15: vCores x GB de RAM por vCore (referencia de la Sku General Purpose)

Sheet Red
A1: Red (Network) — Ancho de banda estimado y transferencia de datos
A3: Concepto | B3: Año 0 (hoy) | C3: Año 1 | D3: Año 2 | E3: Año 3 | F3: Nota / fórmula
A4: A. Ancho de banda pico (subida de archivos + API)
A5: Usuarios concurrentes pico (proyectados) | B5: =Computo!B5 -> 100 | C5: =Computo!C5 -> 120 | D5: =Computo!D5 -> 144 | E5: =Computo!E5 -> 172.8
A6: Usuarios subiendo un archivo simultáneamente (pico) | B6: =B5*Supuestos!$B$43 -> 15 | C6: =C5*Supuestos!$B$43 -> 18 | D6: =D5*Supuestos!$B$43 -> 21.6 | E6: =E5*Supuestos!$B$43 -> 25.92
A7: Tamaño promedio ponderado de archivo (MB) | B7: =(Supuestos!$B$13*Supuestos!$B$14+Supuestos!$B$15*Supuestos!$B$16)/(Supuestos!$B$13+Supuestos!$B$15) -> 5.1875 | C7: =(Supuestos!$B$13*Supuestos!$B$14+Supuestos!$B$15*Supuestos!$B$16)/(Supuestos!$B$13+Supuestos!$B$15) -> 5.1875 | D7: =(Supuestos!$B$13*Supuestos!$B$14+Supuestos!$B$15*Supuestos!$B$16)/(Supuestos!$B$13+Supuestos!$B$15) -> 5.1875 | E7: =(Supuestos!$B$13*Supuestos!$B$14+Supuestos!$B$15*Supuestos!$B$16)/(Supuestos!$B$13+Supuestos!$B$15) -> 5.1875 | F7: Promedio ponderado por cantidad diaria de documentos e imágenes (no cambia por año)
A8: Ancho de banda pico de subida (Mbps) | B8: =(B6*B7*8/Supuestos!$B$44)*(1+Supuestos!$B$47) -> 68.475 | C8: =(C6*C7*8/Supuestos!$B$44)*(1+Supuestos!$B$47) -> 82.17 | D8: =(D6*D7*8/Supuestos!$B$44)*(1+Supuestos!$B$47) -> 98.604 | E8: =(E6*E7*8/Supuestos!$B$44)*(1+Supuestos!$B$47) -> 118.3248 | F8: (usuarios subiendo x tamaño MB x 8 bits / segundos objetivo) x (1+overhead protocolo). MB x 8 = Megabits
A9: Solicitudes API por segundo (pico) | B9: =(B5*Supuestos!$B$46/60) -> 10 | C9: =(C5*Supuestos!$B$46/60) -> 12 | D9: =(D5*Supuestos!$B$46/60) -> 14.4 | E9: =(E5*Supuestos!$B$46/60) -> 17.28 | F9: usuarios concurrentes x solicitudes/usuario/min / 60 seg
A10: Ancho de banda de tráfico API (Mbps) | B10: =(B9*Supuestos!$B$45*8/1000)*(1+Supuestos!$B$47) -> 1.32 | C10: =(C9*Supuestos!$B$45*8/1000)*(1+Supuestos!$B$47) -> 1.584 | D10: =(D9*Supuestos!$B$45*8/1000)*(1+Supuestos!$B$47) -> 1.9008 | E10: =(E9*Supuestos!$B$45*8/1000)*(1+Supuestos!$B$47) -> 2.28096 | F10: solicitudes/seg x KB x 8 bits / 1000 (KB->Mb aprox.) x (1+overhead)
A11: Ancho de banda pico TOTAL estimado (Mbps) | B11: =B8+B10 -> 69.795 | C11: =C8+C10 -> 83.754 | D11: =D8+D10 -> 100.5048 | E11: =E8+E10 -> 120.60576 | F11: Subida de archivos + tráfico API. Usar como insumo para dimensionar WAF/App Gateway/Front Door en el portal de Azure.
A13: B. Transferencia de datos mensual (egress/ingress estimado)
A14: GB/mes por archivos subidos (docs + imágenes) | B14: =Almacenamiento!B6*Supuestos!$B$9/1024 -> 294.22852 | C14: =Almacenamiento!C6*Supuestos!$B$9/1024 -> 353.07422 | D14: =Almacenamiento!D6*Supuestos!$B$9/1024 -> 423.68906 | E14: =Almacenamiento!E6*Supuestos!$B$9/1024 -> 508.42687 | F14: MB generados por día (hoja Almacenamiento) x días hábiles/mes / 1024
A15: GB/mes por tráfico API (ida y vuelta) | B15: =B5*Supuestos!$B$46*60*Supuestos!$B$10*Supuestos!$B$45*Supuestos!$B$9/1024/1024 -> 113.29651 | C15: =C5*Supuestos!$B$46*60*Supuestos!$B$10*Supuestos!$B$45*Supuestos!$B$9/1024/1024 -> 135.95581 | D15: =D5*Supuestos!$B$46*60*Supuestos!$B$10*Supuestos!$B$45*Supuestos!$B$9/1024/1024 -> 163.14697 | E15: =E5*Supuestos!$B$46*60*Supuestos!$B$10*Supuestos!$B$45*Supuestos!$B$9/1024/1024 -> 195.77637 | F15: usuarios concurrentes x solic/min x 60 x horas laborales x KB/solic x días/mes / 1024^2
A16: TOTAL Transferencia de datos estimada (GB/mes) | B16: =B14+B15 -> 407.52502 | C16: =C14+C15 -> 489.03003 | D16: =D14+D15 -> 586.83604 | E16: =E14+E15 -> 704.20324
A18: Nota sobre WAF / Application Gateway:
A19: El dimensionamiento de Azure WAF (Application Gateway v2 o Front Door Premium) se expresa en Capacity Units, que Azure autoescala según tráfico real, reglas OWASP activas e inspección TLS — no existe una fórmula pública simple y confiable para convertir Mbps en Capacity Units sin validarlo en el Azure Pricing Calculator o con pruebas reales. Use el 'Ancho de banda pico TOTAL' de esta hoja como el dato de entrada para esa validación, y contemple autoescalado habilitado desde el diseño.

Sheet Resumen
A1: Resumen Ejecutivo — Dimensionamiento estimado por año
A3: Métrica | B3: Año 0 (hoy) | C3: Año 1 | D3: Año 2 | E3: Año 3 | F3: Referencia / SKU sugerido
A4: Almacenamiento
A5: Total almacenamiento (GB) | B5: =Almacenamiento!B19 -> 3535.6631 | C5: =Almacenamiento!C19 -> 7778.4553 | D5: =Almacenamiento!D19 -> 12869.804 | E5: =Almacenamiento!E19 -> 18979.42 | F5: Azure Blob Storage (Hot tier) + Azure SQL Database
A6: Total almacenamiento (TB) | B6: =Almacenamiento!B20 -> 3.452796 | C6: =Almacenamiento!C20 -> 7.5961478 | D6: =Almacenamiento!D20 -> 12.568168 | E6: =Almacenamiento!E20 -> 18.53459
A8: Cómputo — Capa de Aplicación
A9: vCPU App Tier | B9: =Computo!B7 -> 3 | C9: =Computo!C7 -> 4 | D9: =Computo!D7 -> 4 | E9: =Computo!E7 -> 5
A10: RAM App Tier (GB) | B10: =Computo!B8 -> 7.8 | C10: =Computo!C8 -> 8.58 | D10: =Computo!D8 -> 9.516 | E10: =Computo!E8 -> 10.6392
A11: SKU App Service sugerido (referencia) | B11: =IF(B9<=1,"P0v3 (1 vCPU/4GB)",IF(B9<=2,"P1v3 (2 vCPU/8GB)",IF(B9<=4,"P2v3 (4 vCPU/16GB)",IF(B9<=8,"P3v3 (8 vCPU/32GB)","P4mv3 o superior / escalado horizontal (validar en Azure)")))) -> P2v3 (4 vCPU/16GB) | C11: =IF(C9<=1,"P0v3 (1 vCPU/4GB)",IF(C9<=2,"P1v3 (2 vCPU/8GB)",IF(C9<=4,"P2v3 (4 vCPU/16GB)",IF(C9<=8,"P3v3 (8 vCPU/32GB)","P4mv3 o superior / escalado horizontal (validar en Azure)")))) -> P2v3 (4 vCPU/16GB) | D11: =IF(D9<=1,"P0v3 (1 vCPU/4GB)",IF(D9<=2,"P1v3 (2 vCPU/8GB)",IF(D9<=4,"P2v3 (4 vCPU/16GB)",IF(D9<=8,"P3v3 (8 vCPU/32GB)","P4mv3 o superior / escalado horizontal (validar en Azure)")))) -> P2v3 (4 vCPU/16GB) | E11: =IF(E9<=1,"P0v3 (1 vCPU/4GB)",IF(E9<=2,"P1v3 (2 vCPU/8GB)",IF(E9<=4,"P2v3 (4 vCPU/16GB)",IF(E9<=8,"P3v3 (8 vCPU/32GB)","P4mv3 o superior / escalado horizontal (validar en Azure)")))) -> P3v3 (8 vCPU/32GB) | F11: Referencia orientativa de la familia Premium v3 de Azure App Service. Validar disponibilidad/región y precio en el portal.
A13: Cómputo — Capa de Base de Datos
A14: vCores Azure SQL Database | B14: =Computo!B14 -> 2 | C14: =Computo!C14 -> 2 | D14: =Computo!D14 -> 2 | E14: =Computo!E14 -> 2
A15: RAM aproximada Base de Datos (GB) | B15: =Computo!B15 -> 10.2 | C15: =Computo!C15 -> 10.2 | D15: =Computo!D15 -> 10.2 | E15: =Computo!E15 -> 10.2
A16: SKU Azure SQL sugerido (referencia, General Purpose Gen5) | B16: =IF(B14<=2,"GP_Gen5_2",IF(B14<=4,"GP_Gen5_4",IF(B14<=8,"GP_Gen5_8",IF(B14<=16,"GP_Gen5_16","GP_Gen5_32 o superior / evaluar Business Critical o Hyperscale")))) -> GP_Gen5_2 | C16: =IF(C14<=2,"GP_Gen5_2",IF(C14<=4,"GP_Gen5_4",IF(C14<=8,"GP_Gen5_8",IF(C14<=16,"GP_Gen5_16","GP_Gen5_32 o superior / evaluar Business Critical o Hyperscale")))) -> GP_Gen5_2 | D16: =IF(D14<=2,"GP_Gen5_2",IF(D14<=4,"GP_Gen5_4",IF(D14<=8,"GP_Gen5_8",IF(D14<=16,"GP_Gen5_16","GP_Gen5_32 o superior / evaluar Business Critical o Hyperscale")))) -> GP_Gen5_2 | E16: =IF(E14<=2,"GP_Gen5_2",IF(E14<=4,"GP_Gen5_4",IF(E14<=8,"GP_Gen5_8",IF(E14<=16,"GP_Gen5_16","GP_Gen5_32 o superior / evaluar Business Critical o Hyperscale")))) -> GP_Gen5_2 | F16: Referencia orientativa General Purpose. Si se requiere alta resiliencia/IO, evaluar tier Business Critical.
A18: Red / WAF
A19: Ancho de banda pico total (Mbps) | B19: =Red!B11 -> 69.795 | C19: =Red!C11 -> 83.754 | D19: =Red!D11 -> 100.5048 | E19: =Red!E11 -> 120.60576 | F19: Usar como insumo de entrada para dimensionar Application Gateway v2 (WAF) o Front Door Premium en Azure.
A20: Transferencia de datos estimada (GB/mes) | B20: =Red!B16 -> 407.52502 | C20: =Red!C16 -> 489.03003 | D20: =Red!D16 -> 586.83604 | E20: =Red!E16 -> 704.20324
A22: Notas finales
A23: • Todos los resultados son ÓRDENES DE MAGNITUD para presupuestar y conversar con Azure/el integrador; ajuste los supuestos en la pestaña 'Supuestos' según valide con el negocio.
A24: • Se recomienda validar el dimensionamiento final con el Azure Pricing Calculator, el Well-Architected Framework y, de ser posible, una prueba de carga (load test) antes de contratar los recursos.
A25: • El almacenamiento de archivos (documentos/imágenes) se calculó para Azure Blob Storage; si se requiere alta disponibilidad geográfica, considerar redundancia GRS/ZRS, lo que incrementa el costo (no el espacio útil visto por la app).
A26: • Los reportes en PDF/Excel generados por los usuarios NO se sumaron al Blob Storage en esta versión (solo su metadata en BD); si se van a almacenar los archivos de reporte, agréguelos como una fila adicional en la pestaña Almacenamiento.
