Workbook

Sheet Instrucciones
A1: CÓMO USAR ESTE PLAN DE CONTROL
A3: 1. Fecha de inicio
A4: En la pestaña 'Plan de Control', celda C4, define la fecha real de inicio del proyecto. Todas las fechas de inicio y fin de cada actividad, fase y del proyecto se recalculan automáticamente a partir de ahí (se usan días hábiles de lunes a viernes; no se descuentan días festivos).
A6: 2. Asignar responsables
A7: En la columna 'Responsable' de cada actividad (celdas amarillas), selecciona a la persona del equipo desde la lista desplegable. Puedes editar los nombres del equipo en la hoja oculta 'Listas' (clic derecho en las pestañas > Mostrar).
A9: 3. Actualizar estado y avance
A10: Cada semana, actualiza el 'Estado' (No iniciado / En progreso / Completado / Retrasado / Bloqueado) y el '% Avance' de cada actividad. El avance de cada fase y del proyecto se calcula automáticamente como promedio ponderado por duración.
A12: 4. Días restantes y alertas
A13: La columna 'Días restantes' se calcula sola. Si una actividad no está completada y su fecha fin ya pasó, toda la fila se resalta en rojo para alertarte de un retraso.
A15: 5. Vista Gantt
A16: La pestaña 'Gantt' muestra el calendario visual del proyecto. Las barras verdes son el rango de fechas de cada actividad, las columnas grises son fines de semana y la columna naranja marca el día de hoy. Se actualiza sola si cambias la fecha de inicio.
A18: 6. Resumen ejecutivo
... A22: • No borres ni reordenes filas de la hoja 'Plan de Control': el Gantt y el Resumen dependen de ese orden. • Puedes agregar observaciones libres en la última columna de cada actividad. • Si necesitas agregar días festivos al cálculo, dilo y se puede ajustar la fórmula con WORKDAY.INTL.

Sheet Listas
A1: Responsables | B1: Estado
A2: PM - Líder de Proyecto | B2: No iniciado
A3: Consultor 1 | B3: En progreso
A4: Consultor 2 | B4: Completado
A5: Consultor 3 | B5: Retrasado
A6: Consultor 4 | B6: Bloqueado
A7: Consultor 5
A8: Cliente - Dylo

Sheet Plan de Control
A1: PLAN DE CONTROL DE IMPLEMENTACIÓN — Microsoft 365 Business Premium (Dylo)
A2: Herramienta de seguimiento de actividades, responsables, fechas y avance del proyecto
A4: Fecha de inicio del proyecto: | C4: 46237 | E4: Última actualización: | F4: =TODAY() -> 46238
A5: Celdas amarillas = campos a completar por el PM/equipo. Las fechas y días restantes se calculan solas.
A7: WBS | B7: Actividad / Fase | C7: Responsable | D7: Duración (días) | E7: Inicio | F7: Fin | G7: Estado | H7: % Avance | I7: Días restantes | J7: Observaciones
B8: Implementación Microsoft 365 Business Premium - Dylo | D8: =D9+D18+D28+D37+D47+D56+D66 -> 43 | E8: =E10 -> 46237 | F8: =F70 -> 46295 | G8: =IF(H8=1,"Completado",IF(H8=0,"No iniciado","En progreso")) -> No iniciado | H8: =IFERROR((D9*H9+D18*H18+D28*H28+D37*H37+D47*H47+D56*H56+D66*H66)/(D9+D18+D28+D37+D47+D56+D66),0) -> 0 | I8: =IF(G8="Completado","-",F8-TODAY()) -> 57 | L8: 0 | M8: =L8 -> 0
A9: 1 | B9: Fase 1. Identidad y Acceso (Microsoft Entra ID P1) | D9: =SUM(D10:D17) -> 6 | E9: =E10 -> 46237 | F9: =F17 -> 46244 | G9: =IF(H9=1,"Completado",IF(H9=0,"No iniciado","En progreso")) -> No iniciado | H9: =IFERROR(SUMPRODUCT(D10:D17,H10:H17)/SUM(D10:D17),0) -> 0 | I9: =IF(G9="Completado","-",F9-TODAY()) -> 6 | L9: =M8 -> 0 | M9: =L9 -> 0
A10: 1.1 | B10: Revisión y validación de usuarios, grupos y roles administrativos existentes. | D10: 0.5 | E10: =WORKDAY($C$4-1,INT(L10)+1) -> 46237 | F10: =WORKDAY($C$4-1,ROUNDUP(M10,0)) -> 46237 | G10: No iniciado | H10: 0 | I10: =IF(G10="Completado","-",F10-TODAY()) -> -1 | L10: =M9 -> 0 | M10: =L10+D10 -> 0.5
A11: 1.2 | B11: Habilitación y configuración de autenticación multifactor (MFA) para usuarios incluidos en el alcance. | D11: 1 | E11: =WORKDAY($C$4-1,INT(L11)+1) -> 46237 | F11: =WORKDAY($C$4-1,ROUNDUP(M11,0)) -> 46238 | G11: No iniciado | H11: 0 | I11: =IF(G11="Completado","-",F11-TODAY()) -> 0 | L11: =M10 -> 0.5 | M11: =L11+D11 -> 1.5
A12: 1.3 | B12: Diseño e implementación de políticas de Acceso Condicional basadas en usuario, ubicación, aplicación y estado del dispositivo. | D12: 1 | E12: =WORKDAY($C$4-1,INT(L12)+1) -> 46238 | F12: =WORKDAY($C$4-1,ROUNDUP(M12,0)) -> 46239 | G12: No iniciado | H12: 0 | I12: =IF(G12="Completado","-",F12-TODAY()) -> 1 | L12: =M11 -> 1.5 | M12: =L12+D12 -> 2.5
A13: 1.4 | B13: Configuración de Self-Service Password Reset (SSPR). | D13: 0.5 | E13: =WORKDAY($C$4-1,INT(L13)+1) -> 46239 | F13: =WORKDAY($C$4-1,ROUNDUP(M13,0)) -> 46239 | G13: No iniciado | H13: 0 | I13: =IF(G13="Completado","-",F13-TODAY()) -> 1 | L13: =M12 -> 2.5 | M13: =L13+D13 -> 3
A14: 1.5 | B14: Configuración de Password Protection para fortalecer la política de contraseñas. | D14: 0.5 | E14: =WORKDAY($C$4-1,INT(L14)+1) -> 46240 | F14: =WORKDAY($C$4-1,ROUNDUP(M14,0)) -> 46240 | G14: No iniciado | H14: 0 | I14: =IF(G14="Completado","-",F14-TODAY()) -> 2 | L14: =M13 -> 3 | M14: =L14+D14 -> 3.5
A15: 1.6 | B15: Configuración de grupos administrativos y modelo de acceso basado en roles (RBAC). | D15: 0.5 | E15: =WORKDAY($C$4-1,INT(L15)+1) -> 46240 | F15: =WORKDAY($C$4-1,ROUNDUP(M15,0)) -> 46240 | G15: No iniciado | H15: 0 | I15: =IF(G15="Completado","-",F15-TODAY()) -> 2 | L15: =M14 -> 3.5 | M15: =L15+D15 -> 4
A16: 1.7 | B16: Configuración de Single Sign-On (SSO) para aplicaciones compatibles definidas por Dylo. | D16: 1 | E16: =WORKDAY($C$4-1,INT(L16)+1) -> 46241 | F16: =WORKDAY($C$4-1,ROUNDUP(M16,0)) -> 46241 | G16: No iniciado | H16: 0 | I16: =IF(G16="Completado","-",F16-TODAY()) -> 3 | L16: =M15 -> 4 | M16: =L16+D16 -> 5
A17: 1.8 | B17: Ejecución de pruebas funcionales y validación de acceso seguro. | D17: 1 | E17: =WORKDAY($C$4-1,INT(L17)+1) -> 46244 | F17: =WORKDAY($C$4-1,ROUNDUP(M17,0)) -> 46244 | G17: No iniciado | H17: 0 | I17: =IF(G17="Completado","-",F17-TODAY()) -> 6 | L17: =M16 -> 5 | M17: =L17+D17 -> 6
A18: 2 | B18: Fase 2. Gestión de Dispositivos (Microsoft Intune – MDM) | D18: =SUM(D19:D27) -> 9 | E18: =E19 -> 46245 | F18: =F27 -> 46255 | G18: =IF(H18=1,"Completado",IF(H18=0,"No iniciado","En progreso")) -> No iniciado | H18: =IFERROR(SUMPRODUCT(D19:D27,H19:H27)/SUM(D19:D27),0) -> 0 | I18: =IF(G18="Completado","-",F18-TODAY()) -> 17 | L18: =M17 -> 6 | M18: =L18 -> 6
A19: 2.1 | B19: Definición de estrategia de administración de dispositivos corporativos. | D19: 0.5 | E19: =WORKDAY($C$4-1,INT(L19)+1) -> 46245 | F19: =WORKDAY($C$4-1,ROUNDUP(M19,0)) -> 46245 | G19: No iniciado | H19: 0 | I19: =IF(G19="Completado","-",F19-TODAY()) -> 7 | L19: =M18 -> 6 | M19: =L19+D19 -> 6.5
A20: 2.2 | B20: Configuración de Microsoft Intune como plataforma de Mobile Device Management (MDM). | D20: 0.5 | E20: =WORKDAY($C$4-1,INT(L20)+1) -> 46245 | F20: =WORKDAY($C$4-1,ROUNDUP(M20,0)) -> 46245 | G20: No iniciado | H20: 0 | I20: =IF(G20="Completado","-",F20-TODAY()) -> 7 | L20: =M19 -> 6.5 | M20: =L20+D20 -> 7
A21: 2.3 | B21: Configuración de enrolamiento para dispositivos Windows, macOS, iOS y Android. | D21: 1 | E21: =WORKDAY($C$4-1,INT(L21)+1) -> 46246 | F21: =WORKDAY($C$4-1,ROUNDUP(M21,0)) -> 46246 | G21: No iniciado | H21: 0 | I21: =IF(G21="Completado","-",F21-TODAY()) -> 8 | L21: =M20 -> 7 | M21: =L21+D21 -> 8
A22: 2.4 | B22: Configuración de inscripción automática mediante Microsoft Entra ID. | D22: 0.5 | E22: =WORKDAY($C$4-1,INT(L22)+1) -> 46247 | F22: =WORKDAY($C$4-1,ROUNDUP(M22,0)) -> 46247 | G22: No iniciado | H22: 0 | I22: =IF(G22="Completado","-",F22-TODAY()) -> 9 | L22: =M21 -> 8 | M22: =L22+D22 -> 8.5
A23: 2.5 | B23: Configuración de Windows Autopilot para aprovisionamiento automatizado de equipos Windows. | D23: 2 | E23: =WORKDAY($C$4-1,INT(L23)+1) -> 46247 | F23: =WORKDAY($C$4-1,ROUNDUP(M23,0)) -> 46251 | G23: No iniciado | H23: 0 | I23: =IF(G23="Completado","-",F23-TODAY()) -> 13 | L23: =M22 -> 8.5 | M23: =L23+D23 -> 10.5
A24: 2.6 | B24: Creación de perfiles de configuración para dispositivos administrados. | D24: 1 | E24: =WORKDAY($C$4-1,INT(L24)+1) -> 46251 | F24: =WORKDAY($C$4-1,ROUNDUP(M24,0)) -> 46252 | G24: No iniciado | H24: 0 | I24: =IF(G24="Completado","-",F24-TODAY()) -> 14 | L24: =M23 -> 10.5 | M24: =L24+D24 -> 11.5
A25: 2.7 | B25: Configuración de políticas de cumplimiento (Compliance Policies). | D25: 1 | E25: =WORKDAY($C$4-1,INT(L25)+1) -> 46252 | F25: =WORKDAY($C$4-1,ROUNDUP(M25,0)) -> 46253 | G25: No iniciado | H25: 0 | I25: =IF(G25="Completado","-",F25-TODAY()) -> 15 | L25: =M24 -> 11.5 | M25: =L25+D25 -> 12.5
A26: 2.8 | B26: Habilitación de capacidades de bloqueo remoto, borrado remoto y retiro de información corporativa. | D26: 0.5 | E26: =WORKDAY($C$4-1,INT(L26)+1) -> 46253 | F26: =WORKDAY($C$4-1,ROUNDUP(M26,0)) -> 46253 | G26: No iniciado | H26: 0 | I26: =IF(G26="Completado","-",F26-TODAY()) -> 15 | L26: =M25 -> 12.5 | M26: =L26+D26 -> 13
A27: 2.9 | B27: Pruebas piloto y validación de dispositivos administrados. | D27: 2 | E27: =WORKDAY($C$4-1,INT(L27)+1) -> 46254 | F27: =WORKDAY($C$4-1,ROUNDUP(M27,0)) -> 46255 | G27: No iniciado | H27: 0 | I27: =IF(G27="Completado","-",F27-TODAY()) -> 17 | L27: =M26 -> 13 | M27: =L27+D27 -> 15
A28: 3 | B28: Fase 3. Protección de Aplicaciones (Microsoft Intune – MAM) | D28: =SUM(D29:D36) -> 5 | E28: =E29 -> 46258 | F28: =F36 -> 46262 | G28: =IF(H28=1,"Completado",IF(H28=0,"No iniciado","En progreso")) -> No iniciado | H28: =IFERROR(SUMPRODUCT(D29:D36,H29:H36)/SUM(D29:D36),0) -> 0 | I28: =IF(G28="Completado","-",F28-TODAY()) -> 24 | L28: =M27 -> 15 | M28: =L28 -> 15
A29: 3.1 | B29: Definición de estrategia BYOD para acceso seguro desde dispositivos personales. | D29: 0.5 | E29: =WORKDAY($C$4-1,INT(L29)+1) -> 46258 | F29: =WORKDAY($C$4-1,ROUNDUP(M29,0)) -> 46258 | G29: No iniciado | H29: 0 | I29: =IF(G29="Completado","-",F29-TODAY()) -> 20 | L29: =M28 -> 15 | M29: =L29+D29 -> 15.5
A30: 3.2 | B30: Identificación de aplicaciones Microsoft 365 incluidas en el alcance. | D30: 0.5 | E30: =WORKDAY($C$4-1,INT(L30)+1) -> 46258 | F30: =WORKDAY($C$4-1,ROUNDUP(M30,0)) -> 46258 | G30: No iniciado | H30: 0 | I30: =IF(G30="Completado","-",F30-TODAY()) -> 20 | L30: =M29 -> 15.5 | M30: =L30+D30 -> 16
A31: 3.3 | B31: Configuración de políticas de Mobile Application Management (MAM). | D31: 1 | E31: =WORKDAY($C$4-1,INT(L31)+1) -> 46259 | F31: =WORKDAY($C$4-1,ROUNDUP(M31,0)) -> 46259 | G31: No iniciado | H31: 0 | I31: =IF(G31="Completado","-",F31-TODAY()) -> 21 | L31: =M30 -> 16 | M31: =L31+D31 -> 17
A32: 3.4 | B32: Implementación de controles de acceso a aplicaciones corporativas sin enrolamiento del dispositivo. | D32: 0.5 | E32: =WORKDAY($C$4-1,INT(L32)+1) -> 46260 | F32: =WORKDAY($C$4-1,ROUNDUP(M32,0)) -> 46260 | G32: No iniciado | H32: 0 | I32: =IF(G32="Completado","-",F32-TODAY()) -> 22 | L32: =M31 -> 17 | M32: =L32+D32 -> 17.5
A33: 3.5 | B33: Configuración de restricciones de copia, corte y pegado entre aplicaciones corporativas y personales. | D33: 0.5 | E33: =WORKDAY($C$4-1,INT(L33)+1) -> 46260 | F33: =WORKDAY($C$4-1,ROUNDUP(M33,0)) -> 46260 | G33: No iniciado | H33: 0 | I33: =IF(G33="Completado","-",F33-TODAY()) -> 22 | L33: =M32 -> 17.5 | M33: =L33+D33 -> 18
A34: 3.6 | B34: Implementación de controles de protección de datos corporativos. | D34: 0.5 | E34: =WORKDAY($C$4-1,INT(L34)+1) -> 46261 | F34: =WORKDAY($C$4-1,ROUNDUP(M34,0)) -> 46261 | G34: No iniciado | H34: 0 | I34: =IF(G34="Completado","-",F34-TODAY()) -> 23 | L34: =M33 -> 18 | M34: =L34+D34 -> 18.5
A35: 3.7 | B35: Configuración de borrado selectivo de información empresarial. | D35: 0.5 | E35: =WORKDAY($C$4-1,INT(L35)+1) -> 46261 | F35: =WORKDAY($C$4-1,ROUNDUP(M35,0)) -> 46261 | G35: No iniciado | H35: 0 | I35: =IF(G35="Completado","-",F35-TODAY()) -> 23 | L35: =M34 -> 18.5 | M35: =L35+D35 -> 19
A36: 3.8 | B36: Ejecución de pruebas de acceso y protección de aplicaciones. | D36: 1 | E36: =WORKDAY($C$4-1,INT(L36)+1) -> 46262 | F36: =WORKDAY($C$4-1,ROUNDUP(M36,0)) -> 46262 | G36: No iniciado | H36: 0 | I36: =IF(G36="Completado","-",F36-TODAY()) -> 24 | L36: =M35 -> 19 | M36: =L36+D36 -> 20
A37: 4 | B37: Fase 4. Seguridad de Endpoints (Microsoft Defender for Business) | D37: =SUM(D38:D46) -> 6 | E37: =E38 -> 46265 | F37: =F46 -> 46272 | G37: =IF(H37=1,"Completado",IF(H37=0,"No iniciado","En progreso")) -> No iniciado | H37: =IFERROR(SUMPRODUCT(D38:D46,H38:H46)/SUM(D38:D46),0) -> 0 | I37: =IF(G37="Completado","-",F37-TODAY()) -> 34 | L37: =M36 -> 20 | M37: =L37 -> 20
A38: 4.1 | B38: Configuración inicial de Microsoft Defender for Business. | D38: 0.5 | E38: =WORKDAY($C$4-1,INT(L38)+1) -> 46265 | F38: =WORKDAY($C$4-1,ROUNDUP(M38,0)) -> 46265 | G38: No iniciado | H38: 0 | I38: =IF(G38="Completado","-",F38-TODAY()) -> 27 | L38: =M37 -> 20 | M38: =L38+D38 -> 20.5
A39: 4.2 | B39: Definición de la estrategia de incorporación (Onboarding) de dispositivos. | D39: 0.5 | E39: =WORKDAY($C$4-1,INT(L39)+1) -> 46265 | F39: =WORKDAY($C$4-1,ROUNDUP(M39,0)) -> 46265 | G39: No iniciado | H39: 0 | I39: =IF(G39="Completado","-",F39-TODAY()) -> 27 | L39: =M38 -> 20.5 | M39: =L39+D39 -> 21
A40: 4.3 | B40: Incorporación de dispositivos a Microsoft Defender for Business. | D40: 1 | E40: =WORKDAY($C$4-1,INT(L40)+1) -> 46266 | F40: =WORKDAY($C$4-1,ROUNDUP(M40,0)) -> 46266 | G40: No iniciado | H40: 0 | I40: =IF(G40="Completado","-",F40-TODAY()) -> 28 | L40: =M39 -> 21 | M40: =L40+D40 -> 22
A41: 4.4 | B41: Configuración de Microsoft Defender Antivirus. | D41: 1 | E41: =WORKDAY($C$4-1,INT(L41)+1) -> 46267 | F41: =WORKDAY($C$4-1,ROUNDUP(M41,0)) -> 46267 | G41: No iniciado | H41: 0 | I41: =IF(G41="Completado","-",F41-TODAY()) -> 29 | L41: =M40 -> 22 | M41: =L41+D41 -> 23
A42: 4.5 | B42: Habilitación de protección basada en la nube y protección en tiempo real. | D42: 0.5 | E42: =WORKDAY($C$4-1,INT(L42)+1) -> 46268 | F42: =WORKDAY($C$4-1,ROUNDUP(M42,0)) -> 46268 | G42: No iniciado | H42: 0 | I42: =IF(G42="Completado","-",F42-TODAY()) -> 30 | L42: =M41 -> 23 | M42: =L42+D42 -> 23.5
...

Sheet Gantt
A1: GANTT — Vista de calendario
A2: WBS | B2: Actividad | C2: Responsable | D2: ='Plan de Control'!C$4 -> 46237 | E2: ='Plan de Control'!C$4+1 -> 46238 | F2: ='Plan de Control'!C$4+2 -> 46239 | G2: ='Plan de Control'!C$4+3 -> 46240 | H2: ='Plan de Control'!C$4+4 -> 46241 | I2: ='Plan de Control'!C$4+5 -> 46242 | J2: ='Plan de Control'!C$4+6 -> 46243 | K2: ='Plan de Control'!C$4+7 -> 46244 | L2: ='Plan de Control'!C$4+8 -> 46245 | M2: ='Plan de Control'!C$4+9 -> 46246 | N2: ='Plan de Control'!C$4+10 -> 46247 | O2: ='Plan de Control'!C$4+11 -> 46248 | P2: ='Plan de Control'!C$4+12 -> 46249 | Q2: ='Plan de Control'!C$4+13 -> 46250 | R2: ='Plan de Control'!C$4+14 -> 46251 | S2: ='Plan de Control'!C$4+15 -> 46252 | T2: ='Plan de Control'!C$4+16 -> 46253 | U2: ='Plan de Control'!C$4+17 -> 46254 | V2: ='Plan de Control'!C$4+18 -> 46255 | W2: ='Plan de Control'!C$4+19 -> 46256 | X2: ='Plan de Control'!C$4+20 -> 46257 | Y2: ='Plan de Control'!C$4+21 -> 46258 | Z2: ='Plan de Control'!C$4+22 -> 46259 | AA2: ='Plan de Control'!C$4+23 -> 46260 | AB2: ='Plan de Control'!C$4+24 -> 46261 | AC2: ='Plan de Control'!C$4+25 -> 46262 | AD2: ='Plan de Control'!C$4+26 -> 46263 | AE2: ='Plan de Control'!C$4+27 -> 46264 | AF2: ='Plan de Control'!C$4+28 -> 46265 | AG2: ='Plan de Control'!C$4+29 -> 46266 | AH2: ='Plan de Control'!C$4+30 -> 46267 | AI2: ='Plan de Control'!C$4+31 -> 46268 | AJ2: ='Plan de Control'!C$4+32 -> 46269 | AK2: ='Plan de Control'!C$4+33 -> 46270 | AL2: ='Plan de Control'!C$4+34 -> 46271 | AM2: ='Plan de Control'!C$4+35 -> 46272 | AN2: ='Plan de Control'!C$4+36 -> 46273 | AO2: ='Plan de Control'!C$4+37 -> 46274 | AP2: ='Plan de Control'!C$4+38 -> 46275 | AQ2: ='Plan de Control'!C$4+39 -> 46276 | AR2: ='Plan de Control'!C$4+40 -> 46277 | AS2: ='Plan de Control'!C$4+41 -> 46278 | AT2: ='Plan de Control'!C$4+42 -> 46279 | AU2: ='Plan de Control'!C$4+43 -> 46280 | AV2: ='Plan de Control'!C$4+44 -> 46281 | AW2: ='Plan de Control'!C$4+45 -> 46282 | AX2: ='Plan de Control'!C$4+46 -> 46283 | AY2: ='Plan de Control'!C$4+47 -> 46284 | AZ2: ='Plan de Control'!C$4+48 -> 46285 | BA2: ='Plan de Control'!C$4+49 -> 46286 | BB2: ='Plan de Control'!C$4+50 -> 46287 | BC2: ='Plan de Control'!C$4+51 -> 46288 | BD2: ='Plan de Control'!C$4+52 -> 46289 | BE2: ='Plan de Control'!C$4+53 -> 46290 | BF2: ='Plan de Control'!C$4+54 -> 46291 | BG2: ='Plan de Control'!C$4+55 -> 46292 | BH2: ='Plan de Control'!C$4+56 -> 46293 | BI2: ='Plan de Control'!C$4+57 -> 46294 | BJ2: ='Plan de Control'!C$4+58 -> 46295 | BK2: ='Plan de Control'!C$4+59 -> 46296 | BL2: ='Plan de Control'!C$4+60 -> 46297 | BM2: ='Plan de Control'!C$4+61 -> 46298 | BN2: ='Plan de Control'!C$4+62 -> 46299 | BO2: ='Plan de Control'!C$4+63 -> 46300 | BP2: ='Plan de Control'!C$4+64 -> 46301 | BQ2: ='Plan de Control'!C$4+65 -> 46302 | BR2: ='Plan de Control'!C$4+66 -> 46303 | BS2: ='Plan de Control'!C$4+67 -> 46304 | BT2: ='Plan de Control'!C$4+68 -> 46305 | BU2: ='Plan de Control'!C$4+69 -> 46306
B3: Implementación Microsoft 365 Business Premium - Dylo | C3: ='Plan de Control'!C8 -> 0
A4: 1 | B4: Fase 1. Identidad y Acceso (Microsoft Entra ID P1) | C4: ='Plan de Control'!C9 -> 0
A5: 1.1 | B5: Revisión y validación de usuarios, grupos y roles administrativos existentes. | C5: ='Plan de Control'!C10 -> 0
A6: 1.2 | B6: Habilitación y configuración de autenticación multifactor (MFA) para usuarios incluidos en el alcance. | C6: ='Plan de Control'!C11 -> 0
A7: 1.3 | B7: Diseño e implementación de políticas de Acceso Condicional basadas en usuario, ubicación, aplicación y estado del dispositivo. | C7: ='Plan de Control'!C12 -> 0
A8: 1.4 | B8: Configuración de Self-Service Password Reset (SSPR). | C8: ='Plan de Control'!C13 -> 0
A9: 1.5 | B9: Configuración de Password Protection para fortalecer la política de contraseñas. | C9: ='Plan de Control'!C14 -> 0
A10: 1.6 | B10: Configuración de grupos administrativos y modelo de acceso basado en roles (RBAC). | C10: ='Plan de Control'!C15 -> 0
A11: 1.7 | B11: Configuración de Single Sign-On (SSO) para aplicaciones compatibles definidas por Dylo. | C11: ='Plan de Control'!C16 -> 0
A12: 1.8 | B12: Ejecución de pruebas funcionales y validación de acceso seguro. | C12: ='Plan de Control'!C17 -> 0
A13: 2 | B13: Fase 2. Gestión de Dispositivos (Microsoft Intune – MDM) | C13: ='Plan de Control'!C18 -> 0
A14: 2.1 | B14: Definición de estrategia de administración de dispositivos corporativos. | C14: ='Plan de Control'!C19 -> 0
A15: 2.2 | B15: Configuración de Microsoft Intune como plataforma de Mobile Device Management (MDM). | C15: ='Plan de Control'!C20 -> 0
... A65: 7.4 | B65: Transferencia de conocimiento para consulta y uso de registros de auditoría. | C65: ='Plan de Control'!C70 -> 0

Sheet Resumen
A1: RESUMEN EJECUTIVO DEL PROYECTO
A3: Inicio del proyecto | C3: Fin estimado | E3: Duración total (días hábiles) | G3: % Avance global
A4: ='Plan de Control'!E8 -> 46237 | C4: ='Plan de Control'!F8 -> 46295 | E4: ='Plan de Control'!D8 -> 43 | G4: ='Plan de Control'!H8 -> 0
A6: Total de tareas | B6: Completadas | C6: En progreso | D6: No iniciadas | E6: Retrasadas
A7: =COUNTA('Plan de Control'!G10:G70) -> 61 | B7: =COUNTIF('Plan de Control'!G10:G70,"Completado") -> 0 | C7: =COUNTIF('Plan de Control'!G10:G70,"En progreso") -> 0 | D7: =COUNTIF('Plan de Control'!G10:G70,"No iniciado") -> 61 | E7: =COUNTIF('Plan de Control'!G10:G70,"Retrasado") -> 0
A10: Avance por fase
A11: Fase | B11: Nombre completo | C11: Duración (días) | D11: % Avance
A12: Fase 1 | B12: ='Plan de Control'!B9 -> Fase 1. Identidad y Acceso (Microsoft Entra ID P1) | C12: ='Plan de Control'!D9 -> 6 | D12: ='Plan de Control'!H9 -> 0
A13: Fase 2 | B13: ='Plan de Control'!B18 -> Fase 2. Gestión de Dispositivos (Microsoft Intune – MDM) | C13: ='Plan de Control'!D18 -> 9 | D13: ='Plan de Control'!H18 -> 0
A14: Fase 3 | B14: ='Plan de Control'!B28 -> Fase 3. Protección de Aplicaciones (Microsoft Intune – MAM) | C14: ='Plan de Control'!D28 -> 5 | D14: ='Plan de Control'!H28 -> 0
A15: Fase 4 | B15: ='Plan de Control'!B37 -> Fase 4. Seguridad de Endpoints (Microsoft Defender for Business) | C15: ='Plan de Control'!D37 -> 6 | D15: ='Plan de Control'!H37 -> 0
A16: Fase 5 | B16: ='Plan de Control'!B47 -> Fase 5. Seguridad de Correo y Colaboración (Microsoft Defender for Office 365 Plan 1) | C16: ='Plan de Control'!D47 -> 5 | D16: ='Plan de Control'!H47 -> 0
A17: Fase 6 | B17: ='Plan de Control'!B56 -> Fase 6. Protección de Información (Microsoft Purview Information Protection) | C17: ='Plan de Control'!D56 -> 9 | D17: ='Plan de Control'!H56 -> 0
A18: Fase 7 | B18: ='Plan de Control'!B66 -> Fase 7. Cumplimiento y Gobierno Básico | C18: ='Plan de Control'!D66 -> 3 | D18: ='Plan de Control'!H66 -> 0
